<?xml version="1.0"?>
<robot xmlns:xacro="http://ros.org/wiki/xacro" name="wheel">

	<xacro:macro name="cylinder_inertia" params="m r h">
		<inertia  ixx="${m*(3*r*r+h*h)/12}" ixy = "0" ixz = "0"
			iyy="${m*(3*r*r+h*h)/12}" iyz = "0"
			izz="${m*r*r/2}"
			/>
	</xacro:macro>


	<xacro:macro name="wheel" params="wheel_prefix wheel_mass wheel_radius wheel_thickness parent *origin">
		<link name="${wheel_prefix}_wheel_link">
			<inertial>
				<mass value="${wheel_mass}"/>
				<cylinder_inertia m="${wheel_mass}" r="${wheel_radius}" h="${wheel_thickness}"/>
			</inertial>
			<visual>
				<origin xyz="0 0 0" rpy="${pi/2} 0 0"/>
				<geometry>
					<cylinder length="${wheel_thickness}" radius="${wheel_radius}"/>
				</geometry>
				<material name="black">
					<color rgba="0 0 0 0.5"/>
				</material>
			</visual>
			<collision>
				<origin xyz="0.0 0.0 0" rpy="${pi/2} 0 0"/>
				<geometry>
					<cylinder length="${wheel_thickness}" radius="${wheel_radius}"/>
				</geometry>
			</collision>
		</link>

		<gazebo reference="${wheel_prefix}_wheel_link">
			<mu1 value="1.0"/>
			<mu2 value="1.0"/>
			<kp value="1000000.0" />
			<kd value="1.0" />
			<!--<fdir1 value="1 0 0"/>-->
		</gazebo>

		<joint name="${wheel_prefix}_wheel_joint" type="continuous">
			<parent link="base_link"/>
			<child link="${wheel_prefix}_wheel_link"/>
			<xacro:insert_block name="origin"/>
			<!--<origin xyz="0 0 0" rpy="0 0 0"/>-->
			<!---<joint_properties damping="0.0" friction="0.5"/>-->
			<axis xyz="0 1 0" rpy="0 0 0"/>
		</joint>

		<transmission name="${wheel_prefix}_wheel_transmission">
			<type>transmission_interface/SimpleTransmission</type>
			<!--<type>hardware_interface</type>-->
			<actuator name="${wheel_prefix}_wheel_motor">
				<hardwareInterface>hardware_interface/VelocityJointInterface</hardwareInterface>
				<mechanicalReduction>1</mechanicalReduction>
			</actuator>
			<joint name="${wheel_prefix}_wheel_joint">
				<hardwareInterface>hardware_interface/VelocityJointInterface</hardwareInterface>
			</joint>
		</transmission>

	</xacro:macro>
</robot>
