<?xml version="1.0"?>
<robot name="wheelchair" xmlns:xacro="http://ros.org/wiki/xacro">
    <xacro:include filename="$(find pwm_description)/urdf/defs.urdf.xacro"/>
    <xacro:include filename="$(find pwm_description)/urdf/wheelchairdev.gazebo"/>

    <link name="base_footprint">
    </link>

    <joint name="base_footprint_joint" type="fixed">
        <origin xyz="0 0 ${0.5*14*inch-0.1143}" rpy="0 0 0"/>
        <parent link="base_footprint"/>
        <child link="base_link"/>
    </joint>

    <link
        name="base_link">
        <inertial>
            <origin
                xyz="-5.97916491205108E-05 -5.55111512312578E-17 0.153027812315766"
                rpy="0 0 0" />
            <mass
                value="98.4139630936699" />
            <xacro:box_inertia x="1e-3" y="1e-3" z="1e-3" mass="1e-3"/>
        </inertial>
        <visual>
            <origin
                xyz="0 0 0"
                rpy="0 0 0" />
            <geometry>
                <mesh
                    filename="package://pwm_description/meshes/base_link.STL" />
            </geometry>
            <material
                name="">
                <color
                    rgba="0.792156862745098 0.819607843137255 0.933333333333333 1" />
            </material>
        </visual>
        <collision>
            <origin xyz="0.0 0.0 0.152400001884" rpy="0 0 0"/>
            <geometry>
                <box size="0.711199998856 0.457199990749 0.304800003767"/>
            </geometry>
        </collision>
    </link>

    <link
        name="seat_link">
        <inertial>
            <origin
                xyz="-0.0332097722373201 0.00406938602338047 0.0228912507671721"
                rpy="0 0 0" />
            <mass
                value="39.8904807609114" />
            <inertia
                ixx="0.122921824576847"
                ixy="0.0164619739758286"
                ixz="-0.146470483923146"
                iyy="0.316753450399423"
                iyz="0.0119623440768997"
                izz="0.196633649371876" />
        </inertial>
        <visual>
            <origin
                xyz="0 0 0"
                rpy="0 0 0" />
            <geometry>
                <mesh
                    filename="package://pwm_description/meshes/seat_link.STL" />
            </geometry>
            <material
                name="">
                <color
                    rgba="0.792156862745098 0.819607843137255 0.933333333333333 1" />
            </material>
        </visual>
        <collision>
            <origin xyz="-0.0635000020266 7.45058059692e-09 0.0127000026405" rpy="0 0 0"/>
            <geometry>
                <box size="0.660400032997 0.482599973679 0.228599995375"/>
            </geometry>
        </collision>
    </link>

    <joint
        name="seat_joint"
        type="prismatic">
        <origin
            xyz="0.0889000000000003 -0.0126999999999997 0.50361"
            rpy="0 0 0" />
        <parent
            link="base_link" />
        <child
            link="seat_link" />
        <axis
            xyz="0 0 1" />
        <limit lower="0.0" upper="0.3" effort="1500" velocity="0.5" />
    </joint>

    <link
        name="footrest_link">
        <inertial>
            <origin
                xyz="0.055498 -0.21402 -5.5629E-05"
                rpy="0 0 0" />
            <mass
                value="2.24583004981917" />
            <inertia
                ixx="0.00172839866541921"
                ixy="0.000772961959349029"
                ixz="3.16929282986145E-06"
                iyy="0.00047716278384899"
                iyz="-6.88732971243823E-06"
                izz="0.00207972567905554" />
        </inertial>
        <visual>
            <origin
                xyz="0 0 0"
                rpy="0 0 0" />
            <geometry>
                <mesh
                    filename="package://pwm_description/meshes/footrest_link.STL" />
            </geometry>
            <material
                name="">
                <color
                    rgba="0.792156862745098 0.819607843137255 0.933333333333333 1" />
            </material>
        </visual>
        <collision>
            <!--
                 Disabled due to lidar
            <origin xyz="0.128881782293 -0.200304538012 0.0" rpy="0 0 0"/>
            <geometry>
                <box size="0.30856359005 0.400308251381 0.43180000782"/>
            </geometry>
            -->
            <origin
                xyz="0 0 0"
                rpy="0 0 0" />
            <geometry>
                <mesh
                    filename="package://pwm_description/meshes/footrest_link.STL" />
            </geometry>
        </collision>
    </link>
    <joint
        name="footrest_joint"
        type="fixed">
        <origin
            xyz="0.2667 0 0.0317500000000001"
            rpy="1.5707963267949 0 0" />
        <parent
            link="seat_link" />
        <child
            link="footrest_link" />
        <axis
            xyz="0 0 -1" />
        <!--
        <limit lower="-3.14" upper="3.14" effort="1500" velocity="0.5" />
        -->
    </joint>
    <link
        name="lidar_link">
        <inertial>
            <origin
                xyz="-0.0028645 3.9558E-06 -0.019418"
                rpy="0 0 0" />
            <mass
                value="0.13624" />
            <inertia
                ixx="4.024E-05"
                ixy="1.4318E-08"
                ixz="-6.2254E-08"
                iyy="4.1714E-05"
                iyz="1.0354E-08"
                izz="1.4743E-06" />
        </inertial>
        <visual>
            <origin
                xyz="0 0 0"
                rpy="0 0 0" />
            <geometry>
                <mesh
                    filename="package://pwm_description/meshes/lidar_link.STL" />
            </geometry>
            <material
                name="">
                <color
                    rgba="0.79216 0.81961 0.93333 1" />
            </material>
        </visual>
        <collision>
            <origin xyz="-0.00884072016925 0.0 -0.0141306817532" rpy="0 0 0"/>
            <geometry>
                <box size="0.0632499977946 0.0500000007451 0.070000000298"/>
            </geometry>
        </collision>
    </link>
    <joint
        name="lidar_joint"
        type="fixed">
        <origin
            xyz="0.13695 -0.32488 -0.00060405"
            rpy="-1.5708 8.2132E-18 0.026657" />
        <parent
            link="footrest_link" />
        <child
            link="lidar_link" />
        <axis
            xyz="0 0 1" />
    </joint>
    <link
        name="realsense_link">
        <inertial>
            <origin
                xyz="-0.012211 0.001403 8.0403E-05"
                rpy="0 0 0" />
            <mass
                value="0.050576" />
            <xacro:box_inertia x="1e-2" y="1e-2" z="1e-2" mass="1e-2"/>
        </inertial>
        <visual>
            <origin
                xyz="0 0 0"
                rpy="0 0 0" />
            <geometry>
                <mesh
                    filename="package://pwm_description/meshes/realsense_link.STL" />
            </geometry>
            <material
                name="">
                <color
                    rgba="0.66667 0.69804 0.76863 1" />
            </material>
        </visual>
        <collision>
            <origin xyz="-0.0125249996781 0.0 0.0" rpy="0 0 0"/>
            <geometry>
                <box size="0.0250499993563 0.0900000035763 0.0250000003725"/>
            </geometry>
        </collision>
    </link>
    <joint
        name="realsense_joint"
        type="fixed">
        <origin
            xyz="0.085134 -0.18956 -0.00127"
            rpy="-1.5708 1.5155E-16 0.026657" />
        <parent
            link="footrest_link" />
        <child
            link="realsense_link" />
        <axis
            xyz="0 0 1" />
    </joint>

    <!-- optical frame -->
    <link name="realsense_optical"/>
    <joint name="realsense_optical_joint" type="fixed">
        <origin xyz="0 0 0" rpy="${-pi/2} 0 ${-pi/2}"/>
        <parent link="realsense_link"/>
        <child link="realsense_optical"/>
    </joint>

    <link
        name="back_link">
        <inertial>
            <origin
                xyz="0.06802 0.27418 0.010362"
                rpy="0 0 0" />
            <mass
                value="21.3849460447243" />
            <inertia
                ixx="0.638823322523092"
                ixy="-0.0353788477032128"
                ixz="-0.147324675628681"
                iyy="0.612040467785112"
                iyz="0.00497982785800062"
                izz="0.731113551637578" />
        </inertial>
        <visual>
            <origin
                xyz="0 0 0"
                rpy="0 0 0" />
            <geometry>
                <mesh
                    filename="package://pwm_description/meshes/back_link.STL" />
            </geometry>
            <material
                name="">
                <color
                    rgba="0.792156862745098 0.819607843137255 0.933333333333333 1" />
            </material>
        </visual>
        <collision>
            <origin xyz="0.256545692682 0.355273872614 -0.0322397202253" rpy="0 0 0"/>
            <geometry>
                <box size="0.75830322504 0.710547745228 0.710565447807"/>
            </geometry>
        </collision>
    </link>
    <joint
        name="back_joint"
        type="fixed">
        <origin
            xyz="-0.23495 0 0.127"
            rpy="1.5707963267949 0 0" />
        <parent
            link="seat_link" />
        <child
            link="back_link" />
        <axis
            xyz="0 0 -1" />
        <!--
        <limit lower="-3.14" upper="3.14" effort="1500" velocity="0.5" />
        -->
    </joint>
    <link
        name="gps_link">
        <inertial>
            <origin
                xyz="-0.00052822 0.00021277 0.0091581"
                rpy="0 0 0" />
            <mass
                value="0.026768" />
            <xacro:box_inertia x="1e-2" y="1e-2" z="1e-2" mass="1e-2"/>
        </inertial>
        <visual>
            <origin
                xyz="0 0 0"
                rpy="0 0 0" />
            <geometry>
                <mesh
                    filename="package://pwm_description/meshes/gps_link.STL" />
            </geometry>
            <material
                name="">
                <color
                    rgba="0.29804 0.29804 0.29804 1" />
            </material>
        </visual>
        <collision>
            <origin xyz="-0.00362478382885 0.0 0.00983087625355" rpy="0 0 0"/>
            <geometry>
                <box size="0.0597429461777 0.0525326915085 0.0197107437998"/>
            </geometry>
        </collision>
    </link>
    <joint
        name="gps_joint"
        type="fixed">
        <origin
            xyz="-0.032953 0.4537 -0.0003404"
            rpy="-1.5708 -1.7107E-16 0.10298" />
        <parent
            link="back_link" />
        <child
            link="gps_link" />
        <axis
            xyz="0 0 1" />
    </joint>
    <link
        name="right_wheel_link">
        <inertial>
            <origin
                xyz="5.5511E-17 0 0.032142"
                rpy="0 0 0" />
            <mass
                value="${4.0*lb}" />
            <xacro:cylinder_inertia m="${4.0*lb}" r="${0.5*14*inch}" h="${2.5*inch}"/>
        </inertial>
        <visual>
            <origin
                xyz="0 0 0"
                rpy="0 0 0" />
            <geometry>
                <mesh
                    filename="package://pwm_description/meshes/right_wheel_link.STL" />
            </geometry>
            <material
                name="">
                <color
                    rgba="0.792156862745098 0.819607843137255 0.933333333333333 1" />
            </material>
        </visual>
        <collision>
            <origin
                xyz="0 0 0"
                rpy="0 0 0" />
            <!--
            <geometry>
                <mesh
                    filename="package://pwm_description/meshes/right_wheel_link.STL" />
            </geometry>
            -->
            <geometry>
                <cylinder length="${2.5*inch}" radius="${0.5*14*inch}"/>
            </geometry>
        </collision>
    </link>
    <joint
        name="right_wheel_joint"
        type="continuous">
        <origin
            xyz="0.0254 -0.3048 0.1143"
            rpy="-1.5708 0 0" />
        <parent
            link="base_link" />
        <child
            link="right_wheel_link" />
        <axis
            xyz="0 0 1" />
    </joint>
    <link
        name="left_wheel_link">
        <inertial>
            <origin
                xyz="0 -2.7756E-17 -0.032142"
                rpy="0 0 0" />
            <mass
                value="${4.0*lb}" />
            <xacro:cylinder_inertia m="${4.0*lb}" r="${0.5*14*inch}" h="${2.5*inch}"/>
        </inertial>
        <visual>
            <origin
                xyz="0 0 0"
                rpy="0 0 0" />
            <geometry>
                <mesh
                    filename="package://pwm_description/meshes/left_wheel_link.STL" />
            </geometry>
            <material
                name="">
                <color
                    rgba="0.79216 0.81961 0.93333 1" />
            </material>
        </visual>
        <collision>
            <origin
                xyz="0 0 0"
                rpy="0 0 0" />
            <geometry>
                <cylinder length="${2.5*inch}" radius="${0.5*14*inch}"/>
            </geometry>
        </collision>
    </link>
    <joint
        name="left_wheel_joint"
        type="continuous">
        <origin
            xyz="0.0254 0.3048 0.1143"
            rpy="-1.5708 0 0" />
        <parent
            link="base_link" />
        <child
            link="left_wheel_link" />
        <axis
            xyz="0 0 1" />
    </joint>
    <link
        name="caster_fl_link">
        <inertial>
            <origin
                xyz="-2.2898E-16 6.9389E-18 -0.0010598"
                rpy="0 0 0" />
            <mass
                value="${2.0*lb}" />
            <xacro:cylinder_inertia m="${2.0*lb}" r="${0.5*8*inch}" h="${2.0*inch}"/>
        </inertial>
        <visual>
            <origin
                xyz="0 0 0"
                rpy="0 0 0" />
            <geometry>
                <mesh
                    filename="package://pwm_description/meshes/caster_fl_link.STL" />
            </geometry>
            <material
                name="">
                <color
                    rgba="0.792156862745098 0.819607843137255 0.933333333333333 1" />
            </material>
        </visual>
        <collision>
            <origin
                xyz="0 0 0"
                rpy="0 0 0" />
            <!--
            <geometry>
                <mesh
                    filename="package://pwm_description/meshes/caster_fl_link.STL" />
            </geometry>
            -->
            <geometry>
                <cylinder length="${2.0*inch}" radius="${0.5*8*inch}"/>
            </geometry>
        </collision>
    </link>
    <joint
        name="caster_fl_joint"
        type="fixed">
        <origin
            xyz="0.33655 0.2667 0.0381"
            rpy="1.5708 0 3.1416" />
        <parent
            link="base_link" />
        <child
            link="caster_fl_link" />
        <axis
            xyz="0 0 1" />
    </joint>
    <link
        name="caster_bl_link">
        <inertial>
            <origin
                xyz="1.1102E-16 -2.0817E-16 -0.0010598"
                rpy="0 0 0" />
            <mass
                value="${2.0*lb}" />
            <xacro:cylinder_inertia m="${2.0*lb}" r="${0.5*8*inch}" h="${2.0*inch}"/>
        </inertial>
        <visual>
            <origin
                xyz="0 0 0"
                rpy="0 0 0" />
            <geometry>
                <mesh
                    filename="package://pwm_description/meshes/caster_bl_link.STL" />
            </geometry>
            <material
                name="">
                <color
                    rgba="0.79216 0.81961 0.93333 1" />
            </material>
        </visual>
        <collision>
            <origin
                xyz="0 0 0"
                rpy="0 0 0" />
            <geometry>
                <cylinder length="${2.0*inch}" radius="${0.5*8*inch}"/>
            </geometry>
        </collision>
    </link>
    <joint
        name="caster_bl_joint"
        type="fixed">
        <origin
            xyz="-0.33655 0.2667 0.0381"
            rpy="1.5708 0 3.1416" />
        <parent
            link="base_link" />
        <child
            link="caster_bl_link" />
        <axis
            xyz="0 0 1" />
    </joint>
    <link
        name="caster_fr_link">
        <inertial>
            <origin
                xyz="1.1796E-16 -2.0123E-16 0.0010598"
                rpy="0 0 0" />
            <mass
                value="${2.0*lb}" />
            <xacro:cylinder_inertia m="${2.0*lb}" r="${0.5*8*inch}" h="${2.0*inch}"/>
        </inertial>
        <visual>
            <origin
                xyz="0 0 0"
                rpy="0 0 0" />
            <geometry>
                <mesh
                    filename="package://pwm_description/meshes/caster_fr_link.STL" />
            </geometry>
            <material
                name="">
                <color
                    rgba="0.79216 0.81961 0.93333 1" />
            </material>
        </visual>
        <collision>
            <origin
                xyz="0 0 0"
                rpy="0 0 0" />
            <geometry>
                <cylinder length="${2.0*inch}" radius="${0.5*8*inch}"/>
            </geometry>
        </collision>
    </link>
    <joint
        name="caster_fr_joint"
        type="fixed">
        <origin
            xyz="0.33655 -0.2667 0.0381"
            rpy="1.5708 0 3.1416" />
        <parent
            link="base_link" />
        <child
            link="caster_fr_link" />
        <axis
            xyz="0 0 1" />
    </joint>
    <link
        name="caster_br_link">
        <inertial>
            <origin
                xyz="-5.9792E-05 -5.5511E-17 0.15303"
                rpy="0 0 0" />
            <mass
                value="${2.0*lb}" />
            <xacro:cylinder_inertia m="${2.0*lb}" r="${0.5*8*inch}" h="${2.0*inch}"/>
        </inertial>
        <visual>
            <origin
                xyz="0 0 0"
                rpy="0 0 0" />
            <geometry>
                <mesh
                    filename="package://pwm_description/meshes/caster_br_link.STL" />
            </geometry>
            <material
                name="">
                <color
                    rgba="0.79216 0.81961 0.93333 1" />
            </material>
        </visual>
        <collision>
            <origin
                xyz="0 0 0"
                rpy="0 0 0" />
            <geometry>
                <cylinder length="${2.0*inch}" radius="${0.5*8*inch}"/>
            </geometry>
        </collision>
    </link>
    <joint
        name="caster_br_joint"
        type="fixed">
        <origin
            xyz="-0.33655 -0.2667 0.0381"
            rpy="1.5708 0 3.1416" />
        <parent
            link="base_link" />
        <child
            link="caster_br_link" />
        <axis
            xyz="0 0 1" />
    </joint>

    <!-- transmission -->
    <transmission name="seat_transmission">
        <type>transmission_interface/SimpleTransmission</type>
        <actuator name="seat_motor">
            <hardwareInterface>hardware_interface/VelocityJointInterface</hardwareInterface>
            <mechanicalReduction>1</mechanicalReduction>
        </actuator>
        <joint name="seat_joint">
            <hardwareInterface>hardware_interface/VelocityJointInterface</hardwareInterface>
        </joint>
    </transmission>

</robot>
