<robot
    name="WheelchairDev.SLDASM">
    <link
        name="base_link">
        <inertial>
            <origin
                xyz="-5.9792E-05 -5.5511E-17 0.15303"
                rpy="0 0 0" />
            <mass
                value="98.414" />
            <inertia
                ixx="0"
                ixy="0"
                ixz="0"
                iyy="0"
                iyz="0"
                izz="0" />
        </inertial>
        <visual>
            <origin
                xyz="0 0 0"
                rpy="0 0 0" />
            <geometry>
                <mesh
                    filename="package://WheelchairDev.SLDASM/meshes/base_link.STL" />
            </geometry>
            <material
                name="">
                <color
                    rgba="0.79216 0.81961 0.93333 1" />
            </material>
        </visual>
        <collision>
            <origin
                xyz="0 0 0"
                rpy="0 0 0" />
            <geometry>
                <mesh
                    filename="package://WheelchairDev.SLDASM/meshes/base_link.STL" />
            </geometry>
        </collision>
    </link>
    <link
        name="seat_link">
        <inertial>
            <origin
                xyz="-0.03321 0.0040694 0.022891"
                rpy="0 0 0" />
            <mass
                value="39.89" />
            <inertia
                ixx="0.12292"
                ixy="0.016462"
                ixz="-0.14647"
                iyy="0.31675"
                iyz="0.011962"
                izz="0.19663" />
        </inertial>
        <visual>
            <origin
                xyz="0 0 0"
                rpy="0 0 0" />
            <geometry>
                <mesh
                    filename="package://WheelchairDev.SLDASM/meshes/seat_link.STL" />
            </geometry>
            <material
                name="">
                <color
                    rgba="0.79216 0.81961 0.93333 1" />
            </material>
        </visual>
        <collision>
            <origin
                xyz="0 0 0"
                rpy="0 0 0" />
            <geometry>
                <mesh
                    filename="package://WheelchairDev.SLDASM/meshes/seat_link.STL" />
            </geometry>
        </collision>
    </link>
    <joint
        name="seat_joint"
        type="prismatic">
        <origin
            xyz="0.0889 -0.0127 0.50361"
            rpy="0 0 0" />
        <parent
            link="base_link" />
        <child
            link="seat_link" />
        <axis
            xyz="0 0 1" />
        <limit
            effort="0"
            velocity="0" />
    </joint>
    <link
        name="footrest_link">
        <inertial>
            <origin
                xyz="0.055498 -0.21402 -5.5629E-05"
                rpy="0 0 0" />
            <mass
                value="2.3451" />
            <inertia
                ixx="0.003853"
                ixy="0.0017154"
                ixz="6.8937E-06"
                iyy="0.00085545"
                iyz="-1.3979E-05"
                izz="0.0046214" />
        </inertial>
        <visual>
            <origin
                xyz="0 0 0"
                rpy="0 0 0" />
            <geometry>
                <mesh
                    filename="package://WheelchairDev.SLDASM/meshes/footrest_link.STL" />
            </geometry>
            <material
                name="">
                <color
                    rgba="0.79216 0.81961 0.93333 1" />
            </material>
        </visual>
        <collision>
            <origin
                xyz="0 0 0"
                rpy="0 0 0" />
            <geometry>
                <mesh
                    filename="package://WheelchairDev.SLDASM/meshes/footrest_link.STL" />
            </geometry>
        </collision>
    </link>
    <joint
        name="footrest_joint"
        type="revolute">
        <origin
            xyz="0.2667 0 0.03175"
            rpy="1.5708 0 0" />
        <parent
            link="seat_link" />
        <child
            link="footrest_link" />
        <axis
            xyz="0 0 -1" />
        <limit
            effort="0"
            velocity="0" />
    </joint>
    <link
        name="lidar_link">
        <inertial>
            <origin
                xyz="-0.0028645 3.9558E-06 -0.019418"
                rpy="0 0 0" />
            <mass
                value="0.13624" />
            <inertia
                ixx="4.024E-05"
                ixy="1.4318E-08"
                ixz="-6.2254E-08"
                iyy="4.1714E-05"
                iyz="1.0354E-08"
                izz="1.4743E-06" />
        </inertial>
        <visual>
            <origin
                xyz="0 0 0"
                rpy="0 0 0" />
            <geometry>
                <mesh
                    filename="package://WheelchairDev.SLDASM/meshes/lidar_link.STL" />
            </geometry>
            <material
                name="">
                <color
                    rgba="0.79216 0.81961 0.93333 1" />
            </material>
        </visual>
        <collision>
            <origin
                xyz="0 0 0"
                rpy="0 0 0" />
            <geometry>
                <mesh
                    filename="package://WheelchairDev.SLDASM/meshes/lidar_link.STL" />
            </geometry>
        </collision>
    </link>
    <joint
        name="lidar_joint"
        type="fixed">
        <origin
            xyz="0.13695 -0.32488 -0.00060405"
            rpy="-1.5708 -4.1826E-18 0.026657" />
        <parent
            link="footrest_link" />
        <child
            link="lidar_link" />
        <axis
            xyz="0 0 0" />
    </joint>
    <link
        name="realsense_link">
        <inertial>
            <origin
                xyz="-0.012211 0.001403 8.0403E-05"
                rpy="0 0 0" />
            <mass
                value="0.050576" />
            <inertia
                ixx="0"
                ixy="0"
                ixz="0"
                iyy="0"
                iyz="0"
                izz="0" />
        </inertial>
        <visual>
            <origin
                xyz="0 0 0"
                rpy="0 0 0" />
            <geometry>
                <mesh
                    filename="package://WheelchairDev.SLDASM/meshes/realsense_link.STL" />
            </geometry>
            <material
                name="">
                <color
                    rgba="0.66667 0.69804 0.76863 1" />
            </material>
        </visual>
        <collision>
            <origin
                xyz="0 0 0"
                rpy="0 0 0" />
            <geometry>
                <mesh
                    filename="package://WheelchairDev.SLDASM/meshes/realsense_link.STL" />
            </geometry>
        </collision>
    </link>
    <joint
        name="realsense_joint"
        type="fixed">
        <origin
            xyz="0.085134 -0.18956 -0.00127"
            rpy="-1.5708 1.5155E-16 0.026657" />
        <parent
            link="footrest_link" />
        <child
            link="realsense_link" />
        <axis
            xyz="0 0 0" />
    </joint>
    <link
        name="back_link">
        <inertial>
            <origin
                xyz="0.06802 0.27418 0.010362"
                rpy="0 0 0" />
            <mass
                value="22.009" />
            <inertia
                ixx="0.69033"
                ixy="-0.047591"
                ixz="-0.10483"
                iyy="0.72679"
                iyz="0.014543"
                izz="0.80315" />
        </inertial>
        <visual>
            <origin
                xyz="0 0 0"
                rpy="0 0 0" />
            <geometry>
                <mesh
                    filename="package://WheelchairDev.SLDASM/meshes/back_link.STL" />
            </geometry>
            <material
                name="">
                <color
                    rgba="0.79216 0.81961 0.93333 1" />
            </material>
        </visual>
        <collision>
            <origin
                xyz="0 0 0"
                rpy="0 0 0" />
            <geometry>
                <mesh
                    filename="package://WheelchairDev.SLDASM/meshes/back_link.STL" />
            </geometry>
        </collision>
    </link>
    <joint
        name="back_joint"
        type="revolute">
        <origin
            xyz="-0.23495 0 0.127"
            rpy="1.5708 0 0" />
        <parent
            link="seat_link" />
        <child
            link="back_link" />
        <axis
            xyz="0 0 -1" />
        <limit
            effort="0"
            velocity="0" />
    </joint>
    <link
        name="gps_link">
        <inertial>
            <origin
                xyz="-0.00052822 0.00021277 0.0091581"
                rpy="0 0 0" />
            <mass
                value="0.032213" />
            <inertia
                ixx="0"
                ixy="0"
                ixz="0"
                iyy="0"
                iyz="0"
                izz="0" />
        </inertial>
        <visual>
            <origin
                xyz="0 0 0"
                rpy="0 0 0" />
            <geometry>
                <mesh
                    filename="package://WheelchairDev.SLDASM/meshes/gps_link.STL" />
            </geometry>
            <material
                name="">
                <color
                    rgba="0.1098 0.1098 0.1098 1" />
            </material>
        </visual>
        <collision>
            <origin
                xyz="0 0 0"
                rpy="0 0 0" />
            <geometry>
                <mesh
                    filename="package://WheelchairDev.SLDASM/meshes/gps_link.STL" />
            </geometry>
        </collision>
    </link>
    <joint
        name="gps_joint"
        type="fixed">
        <origin
            xyz="-0.032953 0.4537 -0.0003404"
            rpy="-1.5708 -1.7107E-16 0.10298" />
        <parent
            link="back_link" />
        <child
            link="gps_link" />
        <axis
            xyz="0 0 0" />
    </joint>
    <link
        name="right_wheel_link">
        <inertial>
            <origin
                xyz="5.5511E-17 0 0.032142"
                rpy="0 0 0" />
            <mass
                value="3.7492" />
            <inertia
                ixx="0"
                ixy="0"
                ixz="0"
                iyy="0"
                iyz="0"
                izz="0" />
        </inertial>
        <visual>
            <origin
                xyz="0 0 0"
                rpy="0 0 0" />
            <geometry>
                <mesh
                    filename="package://WheelchairDev.SLDASM/meshes/right_wheel_link.STL" />
            </geometry>
            <material
                name="">
                <color
                    rgba="0.79216 0.81961 0.93333 1" />
            </material>
        </visual>
        <collision>
            <origin
                xyz="0 0 0"
                rpy="0 0 0" />
            <geometry>
                <mesh
                    filename="package://WheelchairDev.SLDASM/meshes/right_wheel_link.STL" />
            </geometry>
        </collision>
    </link>
    <joint
        name="right_wheel_joint"
        type="continuous">
        <origin
            xyz="0.0254 -0.3048 0.1143"
            rpy="-1.5708 0 0" />
        <parent
            link="base_link" />
        <child
            link="right_wheel_link" />
        <axis
            xyz="0 0 1" />
    </joint>
    <link
        name="left_wheel_link">
        <inertial>
            <origin
                xyz="0 -2.7756E-17 -0.032142"
                rpy="0 0 0" />
            <mass
                value="3.7492" />
            <inertia
                ixx="0"
                ixy="0"
                ixz="0"
                iyy="0"
                iyz="0"
                izz="0" />
        </inertial>
        <visual>
            <origin
                xyz="0 0 0"
                rpy="0 0 0" />
            <geometry>
                <mesh
                    filename="package://WheelchairDev.SLDASM/meshes/left_wheel_link.STL" />
            </geometry>
            <material
                name="">
                <color
                    rgba="0.79216 0.81961 0.93333 1" />
            </material>
        </visual>
        <collision>
            <origin
                xyz="0 0 0"
                rpy="0 0 0" />
            <geometry>
                <mesh
                    filename="package://WheelchairDev.SLDASM/meshes/left_wheel_link.STL" />
            </geometry>
        </collision>
    </link>
    <joint
        name="left_wheel_joint"
        type="continuous">
        <origin
            xyz="0.0254 0.3048 0.1143"
            rpy="-1.5708 0 0" />
        <parent
            link="base_link" />
        <child
            link="left_wheel_link" />
        <axis
            xyz="0 0 1" />
    </joint>
    <link
        name="caster_fl_link">
        <inertial>
            <origin
                xyz="-2.2898E-16 6.9389E-18 -0.0010598"
                rpy="0 0 0" />
            <mass
                value="1.2339" />
            <inertia
                ixx="0"
                ixy="0"
                ixz="0"
                iyy="0"
                iyz="0"
                izz="0" />
        </inertial>
        <visual>
            <origin
                xyz="0 0 0"
                rpy="0 0 0" />
            <geometry>
                <mesh
                    filename="package://WheelchairDev.SLDASM/meshes/caster_fl_link.STL" />
            </geometry>
            <material
                name="">
                <color
                    rgba="0.79216 0.81961 0.93333 1" />
            </material>
        </visual>
        <collision>
            <origin
                xyz="0 0 0"
                rpy="0 0 0" />
            <geometry>
                <mesh
                    filename="package://WheelchairDev.SLDASM/meshes/caster_fl_link.STL" />
            </geometry>
        </collision>
    </link>
    <joint
        name="caster_fl_joint"
        type="continuous">
        <origin
            xyz="0.33655 0.2667 0.0381"
            rpy="1.5708 0 3.1416" />
        <parent
            link="base_link" />
        <child
            link="caster_fl_link" />
        <axis
            xyz="0 0 1" />
    </joint>
    <link
        name="caster_bl_link">
        <inertial>
            <origin
                xyz="1.1102E-16 -2.0817E-16 -0.0010598"
                rpy="0 0 0" />
            <mass
                value="1.2339" />
            <inertia
                ixx="0"
                ixy="0"
                ixz="0"
                iyy="0"
                iyz="0"
                izz="0" />
        </inertial>
        <visual>
            <origin
                xyz="0 0 0"
                rpy="0 0 0" />
            <geometry>
                <mesh
                    filename="package://WheelchairDev.SLDASM/meshes/caster_bl_link.STL" />
            </geometry>
            <material
                name="">
                <color
                    rgba="0.79216 0.81961 0.93333 1" />
            </material>
        </visual>
        <collision>
            <origin
                xyz="0 0 0"
                rpy="0 0 0" />
            <geometry>
                <mesh
                    filename="package://WheelchairDev.SLDASM/meshes/caster_bl_link.STL" />
            </geometry>
        </collision>
    </link>
    <joint
        name="caster_bl_joint"
        type="continuous">
        <origin
            xyz="-0.33655 0.2667 0.0381"
            rpy="1.5708 0 3.1416" />
        <parent
            link="base_link" />
        <child
            link="caster_bl_link" />
        <axis
            xyz="0 0 1" />
    </joint>
    <link
        name="caster_fr_link">
        <inertial>
            <origin
                xyz="1.1796E-16 -2.0123E-16 0.0010598"
                rpy="0 0 0" />
            <mass
                value="1.2339" />
            <inertia
                ixx="0"
                ixy="0"
                ixz="0"
                iyy="0"
                iyz="0"
                izz="0" />
        </inertial>
        <visual>
            <origin
                xyz="0 0 0"
                rpy="0 0 0" />
            <geometry>
                <mesh
                    filename="package://WheelchairDev.SLDASM/meshes/caster_fr_link.STL" />
            </geometry>
            <material
                name="">
                <color
                    rgba="0.79216 0.81961 0.93333 1" />
            </material>
        </visual>
        <collision>
            <origin
                xyz="0 0 0"
                rpy="0 0 0" />
            <geometry>
                <mesh
                    filename="package://WheelchairDev.SLDASM/meshes/caster_fr_link.STL" />
            </geometry>
        </collision>
    </link>
    <joint
        name="caster_fr_joint"
        type="continuous">
        <origin
            xyz="0.33655 -0.2667 0.0381"
            rpy="1.5708 0 3.1416" />
        <parent
            link="base_link" />
        <child
            link="caster_fr_link" />
        <axis
            xyz="0 0 1" />
    </joint>
    <link
        name="caster_br_link">
        <inertial>
            <origin
                xyz="-5.9792E-05 -5.5511E-17 0.15303"
                rpy="0 0 0" />
            <mass
                value="98.414" />
            <inertia
                ixx="0"
                ixy="0"
                ixz="0"
                iyy="0"
                iyz="0"
                izz="0" />
        </inertial>
        <visual>
            <origin
                xyz="0 0 0"
                rpy="0 0 0" />
            <geometry>
                <mesh
                    filename="package://WheelchairDev.SLDASM/meshes/caster_br_link.STL" />
            </geometry>
            <material
                name="">
                <color
                    rgba="0.79216 0.81961 0.93333 1" />
            </material>
        </visual>
        <collision>
            <origin
                xyz="0 0 0"
                rpy="0 0 0" />
            <geometry>
                <mesh
                    filename="package://WheelchairDev.SLDASM/meshes/caster_br_link.STL" />
            </geometry>
        </collision>
    </link>
    <joint
        name="caster_br_joint"
        type="continuous">
        <origin
            xyz="-0.33655 -0.2667 0.0381"
            rpy="1.5708 0 3.1416" />
        <parent
            link="base_link" />
        <child
            link="caster_br_link" />
        <axis
            xyz="0 0 1" />
    </joint>
</robot>
